<mujoco model="cheetah">


  <compiler settotalmass="14"/>

  <default>
    <default class="cheetah">
      <joint limited="true" damping=".01" armature=".1" stiffness="8" type="hinge" axis="0 1 0"/>
      <geom contype="1" conaffinity="1" condim="3" friction=".4 .1 .1" material="self"/>
    </default>
    <default class="free">
      <joint limited="false" damping="0" armature="0" stiffness="0"/>
    </default>
    <motor ctrllimited="true" ctrlrange="-1 1"/>
  </default>

  <statistic center="0 0 .7" extent="2"/>

  <option timestep="0.01"/>

  <worldbody>
    <geom name="ground" type="plane" conaffinity="1" pos="98 0 0" size="100 .8 .5" material="grid"/>
    <body name="torso" pos="0 0 1" childclass="cheetah">
      <light name="light" pos="0 0 2" mode="trackcom"/>
      <camera name="side" pos="0 -3 0" quat="0.707 0.707 0 0" mode="trackcom"/>
      <camera name="back" pos="-1.8 -1.3 0.8" xyaxes="0.45 -0.9 0 0.3 0.15 0.94" mode="trackcom"/>
      <joint name="rootx" type="slide" axis="1 0 0" class="free"/>
      <joint name="rootz" type="slide" axis="0 0 1" class="free"/>
      <joint name="rooty" type="slide" axis="0 1 0" class="free"/>
      <joint name="rootr" type="hinge" axis="0 1 0" class="free"/>
      <geom name="torso" type="box" fromto="-.3 0 .25 .3 0 .25" size=".25 .25 .25"/>

      <body name="bthigh" pos="0 0 0">
        <joint name="bfb" range="-30 90" stiffness="240" damping="6"/>
        <joint name="blr" range="-30 30" axis = "1 0 0" stiffness="240" damping="6"/>
        <joint name="btwist" axis="0 0 1"  range="-30 30"/>
        <geom name="bthigh" type="capsule" pos=".1 0 -.13" euler="0 -218 0" size="0.046 .145"/>
          <body name="bshin" pos=".16 0 -.25">
            <joint name="bshin" range="-50 50" stiffness="180" damping="4.5"/>
            <geom name="bshin" type="capsule" pos="-.14 0 -.07" euler="0 -116 0" size="0.046 .15"/>
            <body name="fixed" pos="-.28 0 -.14">
              <joint name="fixed" range="-0.0001 0.0001" />
              <geom name="fixed" type="capsule" pos=".03 0 -.097" euler="0 -20 0" size="0.046 .3"/>
              <body name="bfoot" pos=".12 0 -0.39">
                <joint name="bfoot" range="-60,0" stiffness="180" damping="4.5" />
                <geom name="bfoot" type="capsule" pos=".12 0 -0.03" euler="0 -75 0" size="0.046 .1"/>

            </body>
          </body>
        </body>
      </body>
    </body>

  </worldbody>

  <sensor>
    <subtreelinvel name="torso_subtreelinvel" body="torso"/>
  </sensor>

  <actuator>
    <motor name="bfb" joint="bfb" gear="120" />
    <motor name="blr" joint="blr" gear="120" />
    <motor name="btwist" joint="btwist" gear="120" />
    <motor name="bshin" joint="bshin" gear="90" />
    <motor name = "bfoot" joint = "bfoot" gear = "90" />

  </actuator>
</mujoco>
